Workbook

Sheet DashBoard
B2: EDAN Sismo Cali — Dashboard Reporte 12 de Agosto 2026 - Hora 7:00 Hrs
B3: Se actualiza automáticamente al editar o agregar filas en "EDAN 100826 - Datos Madre" | H3: Casos por comuna
H4: Comuna | I4: Casos
H5: Comuna 1 | I5: =COUNTIF('EDAN 100826 - Datos Madre'!$F$2:$F$2186,"COMUNA 1") -> 9
B6: TOTAL CASOS | D6: PRIORIDAD ALTA | H6: Comuna 10 | I6: =COUNTIF('EDAN 100826 - Datos Madre'!$F$2:$F$2186,"COMUNA 10") -> 34
B7: =COUNTA('EDAN 100826 - Datos Madre'!A2:A2184) -> 863 | D7: =COUNTIF('EDAN 100826 - Datos Madre'!$B$2:$B$2186,"ALTA") -> 48 | H7: Comuna 11 | I7: =COUNTIF('EDAN 100826 - Datos Madre'!$F$2:$F$2186,"COMUNA 11") -> 5
H8: Comuna 13 | I8: =COUNTIF('EDAN 100826 - Datos Madre'!$F$2:$F$2186,"COMUNA 13") -> 4
H9: Comuna 14 | I9: =COUNTIF('EDAN 100826 - Datos Madre'!$F$2:$F$2186,"COMUNA 14") -> 4
H10: Comuna 2 | I10: =COUNTIF('EDAN 100826 - Datos Madre'!$F$2:$F$2186,"COMUNA 2") -> 118
H11: Comuna 21 | I11: =COUNTIF('EDAN 100826 - Datos Madre'!$F$2:$F$2186,"COMUNA 21") -> 5
B12: Casos por color (semáforo) | H12: Comuna 22 | I12: =COUNTIF('EDAN 100826 - Datos Madre'!$F$2:$F$2186,"COMUNA 22") -> 9
B13: Color | C13: Significado | D13: Casos | H13: Comuna 3 | I13: =COUNTIF('EDAN 100826 - Datos Madre'!$F$2:$F$2186,"COMUNA 3") -> 57
B14: Naranja | C14: En atención - Organismos de socorro | D14: =COUNTIF('EDAN 100826 - Datos Madre'!$D$2:$D$2186,"NARANJA") -> 29 | H14: Comuna 4 | I14: =COUNTIF('EDAN 100826 - Datos Madre'!$F$2:$F$2186,"COMUNA 4") -> 11
B15: Morado | C15: En validación - Profesionales Voluntarios | D15: =COUNTIF('EDAN 100826 - Datos Madre'!$D$2:$D$2186,"MORADO") -> 484 | E15: Visitados 294 | F15: En digitalización | H15: Comuna 5 | I15: =COUNTIF('EDAN 100826 - Datos Madre'!$F$2:$F$2186,"COMUNA 5") -> 22
B16: Verde | C16: Atendido | D16: =COUNTIF('EDAN 100826 - Datos Madre'!$D$2:$D$2186,"VERDE") -> 39 | H16: Comuna 6 | I16: =COUNTIF('EDAN 100826 - Datos Madre'!$F$2:$F$2186,"COMUNA 6") -> 9
B17: Amarillo | C17: En validación SGRED | D17: =COUNTIF('EDAN 100826 - Datos Madre'!$D$2:$D$2186,"AMARILLO") -> 14 | H17: Comuna 8 | I17: =COUNTIF('EDAN 100826 - Datos Madre'!$F$2:$F$2186,"COMUNA 8") -> 13
B18: Rojo | C18: Pendiente por atención organismo de socorro | D18: =COUNTIF('EDAN 100826 - Datos Madre'!$D$2:$D$2186,"ROJO") -> 6 | H18: Comuna 9 | I18: =COUNTIF('EDAN 100826 - Datos Madre'!$F$2:$F$2186,"COMUNA 9") -> 38
B19: Sin clasificar | C19: Pendiente por atención | D19: =COUNTIF('EDAN 100826 - Datos Madre'!$D$2:$D$2186,"SIN CLASIFICAR") -> 283
C20: Anulado | D20: =COUNTIF('EDAN 100826 - Datos Madre'!$D$2:$D$2186,"NEGRO") -> 8 | H20: Total | I20: =SUBTOTAL(9,I5:I18) -> 338
B23: Reporte General
C24: Colapsos | E24: Daños | F24: Atrapamientos | G24: Heridos | H24: Rescatados | I24: Fallecidos
B25: TOTALES | C25: 66 | E25: 680 | F25: 174 | G25: 1008 | H25: 88 | I25: 74
C26: Colapsos General
G27: Sujeto a datos recibidos por otras fuentes Virgilio F.
B32: Estado | C32: Colapso Total | D32: Colapso Parcial | E32: Suma
B33: Atendido | C33: =SUMPRODUCT(('EDAN 100826 - Datos Madre'!$R$2:$R$2184=1)*(TRIM('EDAN 100826 - Datos Madre'!$C$2:$C$2184)=$B33)) -> 5 | D33: =SUMPRODUCT(('EDAN 100826 - Datos Madre'!$S$2:$S$2184=1)*(TRIM('EDAN 100826 - Datos Madre'!$C$2:$C$2184)=$B33)) -> 0 | E33: =SUBTOTAL(9,C33:D33) -> 5
B34: En atención | C34: =SUMPRODUCT(('EDAN 100826 - Datos Madre'!$R$2:$R$2184=1)*(TRIM('EDAN 100826 - Datos Madre'!$C$2:$C$2184)=$B34)) -> 24 | D34: =SUMPRODUCT(('EDAN 100826 - Datos Madre'!$S$2:$S$2184=1)*(TRIM('EDAN 100826 - Datos Madre'!$C$2:$C$2184)=$B34)) -> 17 | E34: =SUBTOTAL(9,C34:D34) -> 41
B35: En validación | C35: =SUMPRODUCT(('EDAN 100826 - Datos Madre'!$R$2:$R$2184=1)*(TRIM('EDAN 100826 - Datos Madre'!$C$2:$C$2184)=$B35)) -> 2 | D35: =SUMPRODUCT(('EDAN 100826 - Datos Madre'!$S$2:$S$2184=1)*(TRIM('EDAN 100826 - Datos Madre'!$C$2:$C$2184)=$B35)) -> 0 | E35: =SUBTOTAL(9,C35:D35) -> 2
B36: Pendiente | C36: =SUMPRODUCT(('EDAN 100826 - Datos Madre'!$R$2:$R$2184=1)*(TRIM('EDAN 100826 - Datos Madre'!$C$2:$C$2184)=$B36)) -> 11 | D36: =SUMPRODUCT(('EDAN 100826 - Datos Madre'!$S$2:$S$2184=1)*(TRIM('EDAN 100826 - Datos Madre'!$C$2:$C$2184)=$B36)) -> 11 | E36: =SUBTOTAL(9,C36:D36) -> 22
B37: Validado | C37: =SUMPRODUCT(('EDAN 100826 - Datos Madre'!$R$2:$R$2184=1)*(TRIM('EDAN 100826 - Datos Madre'!$C$2:$C$2184)=$B37)) -> 0 | D37: =SUMPRODUCT(('EDAN 100826 - Datos Madre'!$S$2:$S$2184=1)*(TRIM('EDAN 100826 - Datos Madre'!$C$2:$C$2184)=$B37)) -> 0 | E37: =SUBTOTAL(9,C37:D37) -> 0
B38: ANULADO | C38: =SUMPRODUCT(('EDAN 100826 - Datos Madre'!$R$2:$R$2184=1)*(TRIM('EDAN 100826 - Datos Madre'!$C$2:$C$2184)=$B38)) -> 0 | D38: =SUMPRODUCT(('EDAN 100826 - Datos Madre'!$S$2:$S$2184=1)*(TRIM('EDAN 100826 - Datos Madre'!$C$2:$C$2184)=$B38)) -> 0 | E38: =SUBTOTAL(9,C38:D38) -> 0
B39: Total | C39: =SUBTOTAL(9,C33:C38) -> 42 | D39: =SUBTOTAL(9,D33:D38) -> 28 | E39: =E33+E34+E35+E36+E37+E38 -> 70

Sheet EDAN 100826 - Datos Madre
A1: Consecutivo | B1: Prioridad | C1: Estado | D1: Color semaforo | E1: Urgente | F1: Comuna - Corregimiento | G1: Sector | H1: Barrio | I1: Tipo | K1: Referencia | L1: Direccion completa | M1: Descripción | N1: Normalizacion | O1: Personas Evacuadas | P1: Seres sintientes | Q1: Atencion de la respuesta | R1: Colapso Total | S1: Colapso Parcial | T1: Daños | U1: Atrapamientos | V1: Rescatados | W1: Fallecidos | X1: Hospital/Clinica | Y1: NOMBRE DELEGADO | Z1: Observación Gestión del Riesgo | AA1: SOLICITUDES PENDIENTES | AB1: REFERENCIADO EN EL MAPA | AC1: DESAPARECIDOS | AD1: COORDENADAS | AE1: DESCRIPCION DE LA SITUACION | AF1: Observaciones generales (FORMULARIO)
A2: 1 | B2: ALTA | C2: Atendido | D2: NARANJA | E2: =IF(OR($B2="ALTA",AND(ISNUMBER($W2),$W2>0),AND($U2<>"",$U2<>"NO")),"SI","") -> SI | F2: Comuna 19 | G2: Sur | H2: El Lido | I2: Edificio | J2: Carrera 44 con calle 5 | L2: =CONCATENATE(J2,", ",H2,", Cali") -> Carrera 44 con calle 5, El Lido, Cali | M2: Colapso de 3 edificaciones y 4 en riesgo de colapso | N2: Colapso Estructural | Q2: BROS - DCC | R2: 1 | U2: SI | V2: 7 | W2: 3 | Y2: DANIELA GONZALEZ/MAFE | Z2: En atención se requiere busqueda tecnica. (Bros).. Se asistio con 5 Recursos (máquinas y vehículo de comando), en horas de la noche nos retiramos. El área queda LIMPIA | AA2: Actualización BROS
A3: =A2+1 -> 2 | B3: BAJO | C3: En atención | D3: MORADO | E3: =IF(OR($B3="ALTA",AND(ISNUMBER($W3),$W3>0),AND($U3<>"",$U3<>"NO")),"SI","") | F3: Comuna 17 | G3: Sur | H3: La Hacienda | I3: Edificio | J3: Carrera 72 con calle 11 | L3: =CONCATENATE(J3,", ",H3,", Cali") -> Carrera 72 con calle 11, La Hacienda, Cali | M3: Colapso Estructural | N3: Colapso Estructural | Q3: PROFESIONAL VOLUNTARIO | R3: 1 | U3: NO | Z3: (Bros)...ver punto Nro 20 | AA3: Actualización BROS
A4: =A3+1 -> 3 | B4: BAJO | C4: Visitado | D4: MORADO | E4: =IF(OR($B4="ALTA",AND(ISNUMBER($W4),$W4>0),AND($U4<>"",$U4<>"NO")),"SI","") | F4: Comuna 17 | G4: Sur | H4: Limonar | I4: Edificio | J4: Calle 10 Bis # 70 34 | L4: =CONCATENATE(J4,", ",H4,", Cali") -> Calle 10 Bis # 70 34, Limonar, Cali | M4: Colapso Estructural | N4: Colapso Estructural | Q4: PROFESIONAL VOLUNTARIO | R4: 1 | U4: NO | Z4: (Bros)...ver punto Nro 20 | AA4: Actualización BROS | AD4: 3.3935084, -76.5436393 | AE4: Se encuentra el inmueble en su mayoría con buen estado, parte de la fachada que mira hacia la autopista sur-oriental presenta desprendimiento de elementos no estructurales. Dentro de las zonas comunes se hayan fisuras leves en elementos no estructurales. El bloque b de la unidad presenta daños en las columnas laterales de primer piso, dejando a la vista el acero de refuerzo y dejando una inclinación evidente a simple vista en el muro continuo.
A5: =A4+1 -> 4 | B5: - | C5: ANULADO | D5: NEGRO | E5: - | F5: - | G5: - | H5: - | I5: - | J5: - | K5: - | L5: - | M5: - | N5: - | O5: - | P5: - | Q5: - | R5: - | S5: - | T5: - | U5: - | V5: - | W5: - | X5: - | Y5: - | Z5: - | AA5: - | AB5: -
A6: =A5+1 -> 5 | B6: ALTA | C6: En atención | D6: NARANJA | E6: =IF(OR($B6="ALTA",AND(ISNUMBER($W6),$W6>0),AND($U6<>"",$U6<>"NO")),"SI","") -> SI | F6: Comuna 19 | G6: Sur | H6: Cuarto de Legua | I6: Edificio | J6: Carrera 57 # 3-88 | K6: Edificio Ana del Pilar | L6: =CONCATENATE(J6,", ",H6,", Cali") -> Carrera 57 # 3-88, Cuarto de Legua, Cali | M6: Colapso estructural | N6: Colapso Estructural | Q6: BROS | R6: 1 | U6: SI | V6: 10 | W6: 7 | Z6: Reporte enseguida del D1, no hay personal de bomberos, no hay energía, se necesitan linternas y guantes. (Bros)... Nos encontramos trabajando con varios recursos (aproximadamente 10 vehículos, Bomberos Yumbo) siendo las 23: 20 horas se continua las labores, el área va desde la calle 3 con carrera 50 a la carrera 56. El número de rescatados y fallecidos corresponde al secto indicado. | AA6: Actualización BROS | AB6: DIGITALIZADO
A7: =A6+1 -> 6 | B7: - | C7: ANULADO | D7: NEGRO | E7: - | F7: - | G7: - | H7: - | I7: - | J7: - | K7: - | L7: - | M7: - | N7: - | O7: - | P7: - | Q7: - | R7: - | T7: - | U7: - | V7: - | W7: - | X7: - | Y7: - | Z7: - | AA7: - | AB7: -
A8: =A7+1 -> 7 | B8: ALTA | C8: En atención | D8: NARANJA | E8: =IF(OR($B8="ALTA",AND(ISNUMBER($W8),$W8>0),AND($U8<>"",$U8<>"NO")),"SI","") -> SI | F8: Comuna 19 | G8: Sur | H8: Pampalinda | I8: Edificio | J8: Calle 3 # 61B | K8: Edificio de 3 Pisos | L8: =CONCATENATE(J8,", ",H8,", Cali") -> Calle 3 # 61B, Pampalinda, Cali | M8: Colapso Estructural | N8: Colapso Estructural | Q8: DCC - BROS | R8: 1 | U8: SI | Z8: En atención, salimos la estación alameda en la máquina B2 a la Carrera 61 # 3-167 cuarto de Legua | AA8: Actualización BROS
A9: =A8+1 -> 8 | B9: ALTA | C9: Atendido | D9: VERDE | E9: =IF(OR($B9="ALTA",AND(ISNUMBER($W9),$W9>0),AND($U9<>"",$U9<>"NO")),"SI","") -> SI | F9: Comuna 19 | G9: Sur | H9: Los Cámbulos | I9: Edificio | J9: Av. Roosevelt (Calle 6) con Carrera 42 | L9: =CONCATENATE(J9,", ",H9,", Cali") -> Av. Roosevelt (Calle 6) con Carrera 42, Los Cámbulos, Cali | M9: Daño estructural | N9: Afectación estructural | O9: SI | Q9: BROS | T9: 1 | U9: NO | V9: 5 | Z9: Edificio averiado, se rescata una feminina del sexto piso, lugar acordonado y se da indicacaciones de no habilitar el lugar. (Bros)... = igual información
A10: =A9+1 -> 9 | B10: ALTA | C10: En atención | D10: NARANJA | E10: =IF(OR($B10="ALTA",AND(ISNUMBER($W10),$W10>0),AND($U10<>"",$U10<>"NO")),"SI","") -> SI | F10: Comuna 9 | G10: Sur | H10: Olimpico | I10: Edificio | J10: Carrera 38a # 10 | K10: Edificio Punto Rojo | L10: =CONCATENATE(J10,", ",H10,", Cali") -> Carrera 38a # 10, Olimpico, Cali | M10: Colapso estructural | N10: Colapso Estructural | Q10: RIESGOS - BROS | R10: 1 | U10: 2 | V10: 6 | Y10: Juan Manuel Montaño y Jose Luis Cobo | Z10: Se requiere personal personas atrapadas. (Bros)... Se asitio con dos recursos. ZONA LIMPIA | AA10: Actualización BROS | AB10: Por favor actualizar BOMBEROS - OK DIGITALIZADO
A11: =A10+1 -> 10 | B11: BAJO | C11: Atendido | D11: VERDE | E11: =IF(OR($B11="ALTA",AND(ISNUMBER($W11),$W11>0),AND($U11<>"",$U11<>"NO")),"SI","") | F11: Comuna 19 | G11: Sur | H11: San Fernando | I11: Edificio | J11: Carrera 36 con Calle 5 B2 69 | L11: =CONCATENATE(J11,", ",H11,", Cali") -> Carrera 36 con Calle 5 B2 69, San Fernando, Cali | M11: Daño estructural | N11: Afectación estructural | Q11: RIESGOS | T11: 1 | U11: NO | Y11: Gebel Taba | Z11: Riesgos - Vivienda de dos niveles afectada en fachada. Fractura en paredes de habitación de la parte frontal. Maria Eugenia Ospina.,
A12: =A11+1 -> 11 | B12: ALTA | C12: En atención | D12: AMARILLO | E12: =IF(OR($B12="ALTA",AND(ISNUMBER($W12),$W12>0),AND($U12<>"",$U12<>"NO")),"SI","") -> SI | F12: Comuna 19 | G12: Sur | H12: Cuarto de Legua | I12: Casa | J12: Carrera 58 # 3-138 | L12: =CONCATENATE(J12,", ",H12,", Cali") -> Carrera 58 # 3-138, Cuarto de Legua, Cali | M12: Colapso estructural | N12: Colapso Estructural | Q12: BROS | R12: 1 | U12: 5 | Z12: Familia de 5 personas atrapada - no hay equipos de rescate. (Bros)... Ver punto Nro 6 | AA12: Actualización BROS
A13: =A12+1 -> 12 | B13: BAJO | C13: Atendido | D13: VERDE | E13: =IF(OR($B13="ALTA",AND(ISNUMBER($W13),$W13>0),AND($U13<>"",$U13<>"NO")),"SI","") | F13: Comuna 9 | G13: Centro | H13: Junin | I13: Edificio | J13: Autopista Sur # 13-01 | K13: Hotel La Luna | L13: =CONCATENATE(J13,", ",H13,", Cali") -> Autopista Sur # 13-01, Junin, Cali | M13: Colapso estructural | N13: Colapso Estructural | Q13: CRC | R13: 1 | U13: NO | Y13: Giovanny Ordoñez y Felipe Galves | Z13: Se cayo el hotel la luna, no hay personas atrapadas. (Bros)... No hubo intervención por parte de Bomberos
A14: =A13+1 -> 13 | B14: MEDIO | C14: Pendiente | D14: ROJO | E14: =IF(OR($B14="ALTA",AND(ISNUMBER($W14),$W14>0),AND($U14<>"",$U14<>"NO")),"SI","") | F14: Comuna 19 | G14: Sur | H14: Urbanización Tequendama | I14: Parroquia | J14: Calle 5 con Carrera 42 | K14: Parroquia La Ascensión del Señor | L14: =CONCATENATE(J14,", ",H14,", Cali") -> Calle 5 con Carrera 42, Urbanización Tequendama, Cali | M14: Colapso estructural | N14: Colapso Estructural | R14: 1 | U14: NO | Z14: Se requiere validar, no hubo atención de bomberos. Fuga de gas y maquinaria para buscar 3 víctimas con movilidad reducida Calle 5ta 42 esquina 3235906044 Oscar Aristizábal | AA14: Actualización BROS
A15: =A14+1 -> 14 | B15: ALTA | C15: En atención | D15: NARANJA | E15: =IF(OR($B15="ALTA",AND(ISNUMBER($W15),$W15>0),AND($U15<>"",$U15<>"NO")),"SI","") -> SI | F15: Comuna 5 | G15: Norte | H15: Chiminangos II | I15: Edificio | J15: Calle 62B # 1A9-365 | K15: Torre G | L15: =CONCATENATE(J15,", ",H15,", Cali") -> Calle 62B # 1A9-365, Chiminangos II, Cali | M15: Colapso estructural | N15: Colapso Estructural | Q15: CRC | R15: 1 | T15: 1 | U15: 20 | V15: 3 | Y15: Miguel Medina | Z15: En atención - Priorizado USAR Nacional, Se recomendó evacuación | AA15: Actualización BROS
A16: =A15+1 -> 15 | B16: ALTA | C16: En atención | D16: NARANJA | E16: =IF(OR($B16="ALTA",AND(ISNUMBER($W16),$W16>0),AND($U16<>"",$U16<>"NO")),"SI","") -> SI | F16: Comuna 19 | G16: Sur | H16: Tequendama | I16: Edificio | J16: Carrera 42 con calle 5 | K16: Quintapan | L16: =CONCATENATE(J16,", ",H16,", Cali") -> Carrera 42 con calle 5, Tequendama, Cali | M16: Colapso estructural | N16: Colapso Estructural | Q16: DCC - BROS | R16: 1 | U16: 20 | Z16: Se encuentan en labores de rescate, se requiere apoyo de Seguridad y Justicia; policia con el fin de controlar la aglomeración de personas. | AA16: Actualización BROS | AB16: Por favor actualizar BOMBEROS - OK DIGITALIZADO
A17: =A16+1 -> 16 | B17: ALTA | C17: En atención | D17: NARANJA | E17: =IF(OR($B17="ALTA",AND(ISNUMBER($W17),$W17>0),AND($U17<>"",$U17<>"NO")),"SI","") -> SI | F17: Comuna 19 | G17: Sur | H17: El Refugio | I17: Edificio | J17: Carrera 67 # 3c -15 | K17: Barrio el refugio | L17: =CONCATENATE(J17,", ",H17,", Cali") -> Carrera 67 # 3c -15, El Refugio, Cali | M17: Colapso estructural | N17: Colapso Estructural | Q17: BROS - RIESGOS | R17: 1 | U17: 2 | V17: 4 | W17: 3 | Y17: YESICA JORDAN | Z17: 1. descripcion de la afectación: Edifico de 5 pisos más azotea colapso, 2. se tienen sobrevivientes ya se sacó 1, se necesita urgente personal para ayudar a sacar parece que hay más sobrevivientes, 3. Tienen 2 máquinas de bomberos, 4. Nos indica que ya cruz roja está en este punto, 20 personas están bajo los escombros, 5. Dos torres están evacuadas por posible colapso. (Bros)... Siendo las 23:50 horas continua bomberos trabajando en el sector | AA17: Actualización BROS
A18: =A17+1 -> 17 | B18: - | C18: ANULADO | D18: NARANJA | E18: - | F18: - | G18: - | H18: - | I18: - | J18: - | K18: - | L18: - | M18: - | N18: - | O18: - | P18: - | Q18: - | R18: - | T18: - | U18: - | V18: - | W18: - | X18: - | Y18: - | Z18: - | AA18: - | AB18: -
A19: =A18+1 -> 18 | B19: BAJO | C19: Atendido | D19: VERDE | E19: =IF(OR($B19="ALTA",AND(ISNUMBER($W19),$W19>0),AND($U19<>"",$U19<>"NO")),"SI","") -> SI | F19: Comuna 19 | G19: Oriente | H19: Poblado ll | I19: Hospital | J19: Calle 72U # 28E-00, Poblado II | K19: Hospital Carlos Holmes Trujillo | L19: =CONCATENATE(J19,", ",H19,", Cali") -> Calle 72U # 28E-00, Poblado II, Poblado ll, Cali | M19: Daño estructural | N19: Afectación estructural | Q19: Bomberos - Cruz Ruja | T19: 1 | U19: 12 | X19: 1 | Z19: Atendido - Sin atrapamientos
A20: =A19+1 -> 19 | B20: ALTA | C20: Atendido | D20: VERDE | E20: =IF(OR($B20="ALTA",AND(ISNUMBER($W20),$W20>0),AND($U20<>"",$U20<>"NO")),"SI","") -> SI | F20: Comuna 9 | G20: Centro | H20: San Bosco | I20: Casa | J20: Calle 9 con Carrera 18 | K20: N/A | L20: =CONCATENATE(J20,", ",H20,", Cali") -> Calle 9 con Carrera 18, San Bosco, Cali | M20: Daño estructural | N20: Afectación estructural | O20: SI | Q20: RIESGOS | T20: 1 | U20: NO | V20: 4 | Y20: Alejandro Barrera Daiha Navarro | Z20: Colapso de paredes dos personas sanas, paredes fracturados.
A21: =A20+1 -> 20 | B21: ALTA | C21: Atendido | D21: VERDE | E21: =IF(OR($B21="ALTA",AND(ISNUMBER($W21),$W21>0),AND($U21<>"",$U21<>"NO")),"SI","") -> SI | F21: Comuna 19 | G21: Sur | H21: Tequendama | I21: Casa | J21: Carrera 40 # 4B-26 | K21: N/A | L21: =CONCATENATE(J21,", ",H21,", Cali") -> Carrera 40 # 4B-26, Tequendama, Cali | M21: Daño estructural | N21: Afectación estructural | Q21: BROS | T21: 1 | U21: Validar | V21: 10 | W21: 1 | Z21: 10 edificios afectados. (Bros)... Se asistio con dos recursos. ZONA LIMPIA
A22: =A21+1 -> 21 | B22: - | C22: ANULADO | D22: NARANJA | E22: - | F22: - | G22: - | H22: - | I22: - | J22: - | K22: - | L22: - | M22: - | N22: - | O22: - | P22: - | Q22: - | R22: - | T22: - | U22: - | V22: - | W22: - | X22: - | Y22: - | Z22: - | AA22: - | AB22: -
A23: =A22+1 -> 22 | B23: ALTA | C23: En atención | D23: NARANJA | E23: =IF(OR($B23="ALTA",AND(ISNUMBER($W23),$W23>0),AND($U23<>"",$U23<>"NO")),"SI","") -> SI | F23: Comuna 19 | G23: Sur | H23: Eucarístico | I23: Casa | J23: Calle 10 38 21 | K23: Molino Rojo | L23: =CONCATENATE(J23,", ",H23,", Cali") -> Calle 10 38 21, Eucarístico, Cali | M23: Colapso estructural | N23: Colapso Estructural | Q23: DCC - BROS - MOVIIDAD - POLICIA | R23: 1 | U23: 2 | V23: 8 | Z23: En atención. (Bros)...Se asitio con dos recursos. ZONA LIMPIA | AA23: Actualización BROS
A24: =A23+1 -> 23 | B24: BAJO | C24: Atendido | D24: VERDE | E24: =IF(OR($B24="ALTA",AND(ISNUMBER($W24),$W24>0),AND($U24<>"",$U24<>"NO")),"SI","") -> SI | F24: Comuna 19 | G24: Sur | H24: El Lido | I24: Casa | J24: Carrera 52 # 3 20 | K24: Bodega de reciclaje | L24: =CONCATENATE(J24,", ",H24,", Cali") -> Carrera 52 # 3 20, El Lido, Cali | M24: Colapso estructural | N24: Colapso Estructural | O24: SI | Q24: BROS | R24: 1 | U24: NO | W24: 2 | Z24: Atendido, sin personas atrapadas
A25: =A24+1 -> 24 | B25: ALTA | C25: Pendiente | D25: SIN CLASIFICAR | E25: =IF(OR($B25="ALTA",AND(ISNUMBER($W25),$W25>0),AND($U25<>"",$U25<>"NO")),"SI","") -> SI | F25: Comuna 19 | G25: Sur | H25: Eucarístico | I25: Casa | J25: Carrera 38A # 6 38 | K25: N/A | L25: =CONCATENATE(J25,", ",H25,", Cali") -> Carrera 38A # 6 38, Eucarístico, Cali | M25: Daño estructural | N25: Afectación estructural | T25: 1 | Z25: Se requiere validar
A26: =A25+1 -> 25 | B26: ALTA | C26: Pendiente | D26: SIN CLASIFICAR | E26: =IF(OR($B26="ALTA",AND(ISNUMBER($W26),$W26>0),AND($U26<>"",$U26<>"NO")),"SI","") -> SI | F26: Comuna 3 | G26: Centro | H26: Centro | I26: Edificio | J26: Carrera 5 # 13 46 | K26: Edificio el cafe | L26: =CONCATENATE(J26,", ",H26,", Cali") -> Carrera 5 # 13 46, Centro, Cali | M26: Daño estructural | N26: Afectación estructural | T26: 1 | Z26: Se requiere validar
A27: =A26+1 -> 26 | B27: MEDIO | C27: Pendiente | D27: SIN CLASIFICAR | E27: =IF(OR($B27="ALTA",AND(ISNUMBER($W27),$W27>0),AND($U27<>"",$U27<>"NO")),"SI","") | F27: Comuna 19 | G27: Sur | H27: Cuarto de Legua | I27: Casa | J27: CRE 52 # 2-01 | K27: Coliseo Pueblo | L27: =CONCATENATE(J27,", ",H27,", Cali") -> CRE 52 # 2-01, Cuarto de Legua, Cali | M27: Daño estructural | N27: Afectación estructural | T27: 1 | Z27: Se requiere validar
A28: =A27+1 -> 27 | B28: ALTA | C28: En atención | D28: NARANJA | E28: =IF(OR($B28="ALTA",AND(ISNUMBER($W28),$W28>0),AND($U28<>"",$U28<>"NO")),"SI","") -> SI | F28: Comuna 19 | G28: Sur | H28: Los Cámbulos | I28: Colegio | J28: Carrera 44 con Calle 9 35 | K28: Colegio Adventista | L28: =CONCATENATE(J28,", ",H28,", Cali") -> Carrera 44 con Calle 9 35, Los Cámbulos, Cali | M28: Colapso estructural - Edificación de 8 pisos colapsada, aproximadamente 28 personas atrapadas. Fuga de gas, Edificio de 7 pisos | N28: Colapso Estructural | Q28: GAS - DCC - BROS PROFESIONAL VOLUNTARIO | R28: 1 | U28: 29 (niños) | W28: 2 | Y28: NATHALIE GARCIA - EVELIN COLLAZOS - ERON CISNEROS - MARIA ISABEL | Z28: PUNTO CRITICO En atención - asistio ICBF Equipo psicosicial y unidades moviles. (Bros)...siendo las 01:00 horas del día 11 de agosto continuamos con las labores | AA28: Actualización BROS
A29: =A28+1 -> 28 | B29: ALTA | C29: En atención | D29: NARANJA | E29: =IF(OR($B29="ALTA",AND(ISNUMBER($W29),$W29>0),AND($U29<>"",$U29<>"NO")),"SI","") -> SI | F29: Comuna 17 | G29: Sur | H29: El Limonar | I29: Edificio | J29: Carrera 72 # 10 Bis-21 | K29: Edificio Torres del Limonar | L29: =CONCATENATE(J29,", ",H29,", Cali") -> Carrera 72 # 10 Bis-21, El Limonar, Cali | M29: Colapso estructural - Niña atrapada | N29: Colapso Estructural | Q29: BROS - CRC | R29: 1 | U29: 11 | V29: 7 | Y29: DANIELA CARDONA | Z29: PUNTO CRITICO En atención - COL 19, se encuentra BOMBEROS BOGOTÁ. (Bros)...ver punto Nro 20 | AA29: Actualización BROS
A30: =A29+1 -> 29 | B30: ALTA | C30: Pendiente | D30: SIN CLASIFICAR | E30: =IF(OR($B30="ALTA",AND(ISNUMBER($W30),$W30>0),AND($U30<>"",$U30<>"NO")),"SI","") -> SI | F30: Comuna 19 | G30: Sur | H30: Tequendama | I30: Casa | J30: Calle 5E # 40 - 36 | L30: =CONCATENATE(J30,", ",H30,", Cali") -> Calle 5E # 40 - 36, Tequendama, Cali | M30: Daño estructural | N30: Afectación estructural | Q30: RIESGOS | T30: 1 | U30: Validar | Y30: CAMILA LOZANO MIGUEL LOPEZ | Z30: En validación
A31: =A30+1 -> 30 | B31: - | C31: ANULADO | D31: VERDE | E31: - | F31: - | G31: - | H31: - | I31: - | J31: - | K31: - | L31: - | M31: - | N31: - | O31: - | P31: - | Q31: - | R31: - | T31: - | U31: - | V31: - | W31: - | X31: - | Y31: - | Z31: - | AA31: - | AB31: -
A32: =A31+1 -> 31 | B32: BAJO | C32: En atención | D32: MORADO | E32: =IF(OR($B32="ALTA",AND(ISNUMBER($W32),$W32>0),AND($U32<>"",$U32<>"NO")),"SI","") | F32: Comuna 3 | G32: Centro | H32: San Pedro | I32: Tipo | J32: Calle 14 #5-20 | K32: Centro comercial la fortuna | L32: =CONCATENATE(J32,", ",H32,", Cali") -> Calle 14 #5-20, San Pedro, Cali | M32: Daño estructural | N32: Afectación estructural | O32: SI | Q32: PROFESIONAL VOLUNTARIO | T32: 1
A33: =A32+1 -> 32 | B33: MEDIO | C33: En atención | D33: NARANJA | E33: =IF(OR($B33="ALTA",AND(ISNUMBER($W33),$W33>0),AND($U33<>"",$U33<>"NO")),"SI","") | F33: comuna 9 | G33: Centro | H33: Alameda | I33: Edificio | J33: Calle 9 con carrera 22 | L33: =CONCATENATE(J33,", ",H33,", Cali") -> Calle 9 con carrera 22, Alameda, Cali | M33: Daño estructural | N33: Afectación estructural | O33: SI | Q33: BROS | T33: 1 | V33: 3 | Z33: En atención | AA33: Actualización BROS
A34: =A33+1 -> 33 | B34: BAJO | C34: En atención | D34: MORADO | E34: =IF(OR($B34="ALTA",AND(ISNUMBER($W34),$W34>0),AND($U34<>"",$U34<>"NO")),"SI","") | F34: Comuna 5 | G34: Norte | H34: Torres de Comfandi | I34: Edificio | J34: Calle 62 carrera 1b | L34: =CONCATENATE(J34,", ",H34,", Cali") -> Calle 62 carrera 1b, Torres de Comfandi, Cali | M34: Daño estructural | N34: Afectación estructural | Q34: PROFESIONAL VOLUNTARIO | T34: 1
A35: =A34+1 -> 34 | B35: BAJO | C35: En atención | D35: MORADO | E35: =IF(OR($B35="ALTA",AND(ISNUMBER($W35),$W35>0),AND($U35<>"",$U35<>"NO")),"SI","") | F35: Comuna 3 | G35: Centro | H35: San Pedro | I35: Parroquia | J35: Calle 9 #5-59 | K35: Iglesia san fracisco | L35: =CONCATENATE(J35,", ",H35,", Cali") -> Calle 9 #5-59, San Pedro, Cali | M35: Daño estructural | N35: Afectación estructural | Q35: PROFESIONAL VOLUNTARIO | T35: 1
A36: =A35+1 -> 35 | B36: BAJO | C36: En atención | D36: MORADO | E36: =IF(OR($B36="ALTA",AND(ISNUMBER($W36),$W36>0),AND($U36<>"",$U36<>"NO")),"SI","") | F36: Comuna 3 | G36: Centro | H36: San Bosco | I36: Edificio | J36: carrera 10 calle 5 | L36: =CONCATENATE(J36,", ",H36,", Cali") -> carrera 10 calle 5, San Bosco, Cali | M36: Daño estructural | N36: Afectación estructural | Q36: PROFESIONAL VOLUNTARIO | T36: 1
A37: =A36+1 -> 36 | B37: BAJO | C37: En atención | D37: MORADO | E37: =IF(OR($B37="ALTA",AND(ISNUMBER($W37),$W37>0),AND($U37<>"",$U37<>"NO")),"SI","") -> SI | F37: Comuna 5 | G37: Norte | H37: Chiminangos II | I37: Edificio | J37: Calle 62B # 1A-2-50 | K37: Sector 3 – Chiminangos | L37: =CONCATENATE(J37,", ",H37,", Cali") -> Calle 62B # 1A-2-50, Chiminangos II, Cali | M37: Daño estructural | N37: Afectación estructural | Q37: PROFESIONAL VOLUNTARIO | T37: 1 | U37: 2 | W37: 1 | Z37: Pendiente reporte fallecido
A38: =A37+1 -> 37 | B38: BAJO | C38: En atención | D38: MORADO | E38: =IF(OR($B38="ALTA",AND(ISNUMBER($W38),$W38>0),AND($U38<>"",$U38<>"NO")),"SI","") | F38: Comuna 10 | G38: Sur | H38: Colseguros | I38: Clinica | J38: Calle 10 #33-51 | K38: Clínica Nuestra Señora del Rosario | L38: =CONCATENATE(J38,", ",H38,", Cali") -> Calle 10 #33-51, Colseguros, Cali | M38: Daño estructural | N38: Alto Riesgo de Colapso | O38: SI | Q38: RIESGOS / PROFESIONAL VOLUNTARIO | T38: 1 | X38: 1 | Z38: Evacuación completa, en alto riesgo de colapso Se recmendó evacuación
A39: =A38+1 -> 38 | B39: BAJO | C39: En atención | D39: MORADO | E39: =IF(OR($B39="ALTA",AND(ISNUMBER($W39),$W39>0),AND($U39<>"",$U39<>"NO")),"SI","") -> SI | F39: Comuna 5 | G39: Norte | H39: Barranquilla | I39: Edificio | J39: carrera 1 bis con calle 59 | L39: =CONCATENATE(J39,", ",H39,", Cali") -> carrera 1 bis con calle 59, Barranquilla, Cali | M39: Daño estructural | N39: Afectación estructural | Q39: PROFESIONAL VOLUNTARIO | T39: 1 | W39: 1 | Y39: Juan David Lopez | Z39: Se requiere evacuacion 910 verde
A40: =A39+1 -> 39 | B40: BAJO | C40: En atención | D40: MORADO | E40: =IF(OR($B40="ALTA",AND(ISNUMBER($W40),$W40>0),AND($U40<>"",$U40<>"NO")),"SI","") | F40: Comuna 19 | G40: Sur | H40: Nuevo Tequendama | I40: Edificio | J40: Calle 5 e 46 82 conunto 4 apto 302 b | K40: Torres de santiagp de cali | L40: =CONCATENATE(J40,", ",H40,", Cali") -> Calle 5 e 46 82 conunto 4 apto 302 b, Nuevo Tequendama, Cali | M40: Daño estructural | N40: Afectación estructural | Q40: PROFESIONAL VOLUNTARIO | T40: 1
...

Sheet Tabla dinámica 10

Sheet Tabla dinámica 9

Sheet Datos5-Atendido
B1: Prioridad | C1: Estado | D1: Color semaforo | E1: Urgente | F1: Comuna - Corregimiento | G1: Sector | H1: Barrio | I1: Tipo | J1: Direccion | K1: Referencia | L1: Direccion completa | M1: Descripción | N1: Normalizacion | O1: Personas Evacuadas | P1: Seres sintientes | Q1: Atencion de la respuesta | R1: Colapso Total | S1: Colapso Parcial | T1: Daños | U1: Atrapamientos | V1: Rescatados | W1: Fallecidos | X1: Hospital/Clinica | Y1: NOMBRE DELEGADO | Z1: Observación Gestión del Riesgo | AA1: SOLICITUDES PENDIENTES | AB1: REFERENCIADO EN EL MAPA | AC1: DESAPARECIDOS | AD1: COORDENADAS
A2: 1 | B2: ALTA | C2: Atendido | D2: NARANJA | E2: SI | F2: Comuna 19 | G2: Sur | H2: El Lido | I2: Edificio | J2: Carrera 44 con calle 5 | L2: Carrera 44 con calle 5, El Lido, Cali | M2: Colapso de 3 edificaciones y 4 en riesgo de colapso | N2: Colapso Estructural | Q2: BROS - DCC | R2: 1 | U2: SI | V2: 7 | W2: 3 | Y2: DANIELA GONZALEZ/MAFE | Z2: En atención se requiere busqueda tecnica. (Bros).. Se asistio con 5 Recursos (máquinas y vehículo de comando), en horas de la noche nos retiramos. El área queda LIMPIA | AA2: Actualización BROS
A3: 12 | B3: BAJO | C3: Atendido | D3: VERDE | F3: Comuna 9 | G3: Centro | H3: Junin | I3: Edificio | J3: Autopista Sur # 13-01 | K3: Hotel La Luna | L3: Autopista Sur # 13-01, Junin, Cali | M3: Colapso estructural | N3: Colapso Estructural | Q3: CRC | R3: 1 | U3: NO | Y3: Giovanny Ordoñez y Felipe Galves | Z3: Se cayo el hotel la luna, no hay personas atrapadas. (Bros)... No hubo intervención por parte de Bomberos
A4: 23 | B4: BAJO | C4: Atendido | D4: VERDE | E4: SI | F4: Comuna 19 | G4: Sur | H4: El Lido | I4: Casa | J4: Carrera 52 # 3 20 | K4: Bodega de reciclaje | L4: Carrera 52 # 3 20 , El Lido, Cali | M4: Colapso estructural | N4: Colapso Estructural | O4: SI | Q4: BROS | R4: 1 | U4: NO | W4: 2 | Z4: Atendido, sin personas atrapadas
A5: 83 | B5: MEDIO | C5: Atendido | D5: VERDE | F5: Comuna 19 | G5: Sur | H5: San Fernando | I5: Edificio | J5: Carrera 37 # 5b1 - 37 | K5: Edificio Liliana | L5: Carrera 37 # 5b1 - 37 , San Fernando, Cali | M5: Colapso estructural | N5: Colapso estructural | O5: SI | R5: 1 | Z5: Edificio de 4 pisos con colapso total 10 apartamentos

Sheet Datos4-En validación -Colapso E
B1: Prioridad | C1: Estado | D1: Color semaforo | E1: Urgente | F1: Comuna - Corregimiento | G1: Sector | H1: Barrio | I1: Tipo | J1: Direccion | K1: Referencia | L1: Direccion completa | M1: Descripción | N1: Normalizacion | O1: Personas Evacuadas | P1: Seres sintientes | Q1: Atencion de la respuesta | R1: Colapso Total | S1: Colapso Parcial | T1: Daños | U1: Atrapamientos | V1: Rescatados | W1: Fallecidos | X1: Hospital/Clinica | Y1: NOMBRE DELEGADO | Z1: Observación Gestión del Riesgo | AA1: SOLICITUDES PENDIENTES | AB1: REFERENCIADO EN EL MAPA | AC1: DESAPARECIDOS
A2: 98 | B2: ALTA | C2: En validación | D2: AMARILLO | E2: SI | F2: Comuna 19 | G2: Sur | H2: San Fernando | I2: Casa | J2: Carrera 39/38A # 5d - 09 | L2: Carrera 39/38A # 5d - 09, San Fernando, Cali | M2: Colapso Estructural | N2: Colapso Estructural | Q2: PAZ Y CULTURA | R2: 1 | U2: SI | Y2: Francisco Qesada y patricia de la pava | Z2: Colapso de infraestructura
A3: 113 | B3: MEDIO | C3: En validación | D3: AMARILLO | F3: Comuna 18 | G3: Sur | H3: Alto Jordan | I3: Edificio | J3: Carrera 94d # calle 2 a bis - entre carreras 94c1 y 94b1 | L3: Carrera 94d # calle 2 a bis - entre carreras 94c1 y 94b1, Alto Jordan , Cali | M3: Colapso estructural | N3: Colapso Estructural | Q3: EDRU | R3: 1 | Y3: Carolina Soto - Juan Cralos

Sheet Datos3-Atendido-Colapso Estruct
B1: Prioridad | C1: Estado | D1: Color semaforo | E1: Urgente | F1: Comuna - Corregimiento | G1: Sector | H1: Barrio | I1: Tipo | J1: Direccion | K1: Referencia | L1: Direccion completa | M1: Descripción | N1: Normalizacion | O1: Personas Evacuadas | P1: Seres sintientes | Q1: Atencion de la respuesta | R1: Colapso Total | S1: Colapso Parcial | T1: Daños | U1: Atrapamientos | V1: Rescatados | W1: Fallecidos | X1: Hospital/Clinica | Y1: NOMBRE DELEGADO | Z1: Observación Gestión del Riesgo | AA1: SOLICITUDES PENDIENTES | AB1: REFERENCIADO EN EL MAPA | AC1: DESAPARECIDOS
A2: 1 | B2: ALTA | C2: Atendido | D2: NARANJA | E2: SI | F2: Comuna 19 | G2: Sur | H2: El Lido | I2: Edificio | J2: Carrera 44 con calle 5 | L2: Carrera 44 con calle 5, El Lido, Cali | M2: Colapso de 3 edificaciones y 4 en riesgo de colapso | N2: Colapso Estructural | Q2: BROS - DCC | R2: 1 | U2: SI | V2: 7 | W2: 3 | Y2: DANIELA GONZALEZ/MAFE | Z2: En atención se requiere busqueda tecnica. (Bros).. Se asistio con 5 Recursos (máquinas y vehículo de comando), en horas de la noche nos retiramos. El área queda LIMPIA | AA2: Actualización BROS
A3: 12 | B3: BAJO | C3: Atendido | D3: VERDE | F3: Comuna 9 | G3: Centro | H3: Junin | I3: Edificio | J3: Autopista Sur # 13-01 | K3: Hotel La Luna | L3: Autopista Sur # 13-01, Junin, Cali | M3: Colapso estructural | N3: Colapso Estructural | Q3: CRC | R3: 1 | U3: NO | Y3: Giovanny Ordoñez y Felipe Galves | Z3: Se cayo el hotel la luna, no hay personas atrapadas. (Bros)... No hubo intervención por parte de Bomberos
A4: 23 | B4: BAJO | C4: Atendido | D4: VERDE | E4: SI | F4: Comuna 19 | G4: Sur | H4: El Lido | I4: Casa | J4: Carrera 52 # 3 20 | K4: Bodega de reciclaje | L4: Carrera 52 # 3 20 , El Lido, Cali | M4: Colapso estructural | N4: Colapso Estructural | O4: SI | Q4: BROS | R4: 1 | U4: NO | W4: 2 | Z4: Atendido, sin personas atrapadas

Sheet 901
A1: LA FLORA | B1: AVENIDA 6A CON 35 NOTARIA QUINTA | C1: 1 ADULTO | D1: MASCULINO | E1: 1
A2: LA FLORA | B2: CLL 7 CON 21 | C2: 1 ADULTO | D2: FEMENINO | E2: 1
A3: LIDO | B3: CR 56 d3-150B CUARTO DE LEGUA | C3: 3 FALLECIDOS MUJERES | D3: FEMENINA | E3: 3
A4: LIMONAR | B4: CRA 98B-48 127 EDIFICIO RESIDENCIAL SANTA ANA | C4: 01 FALLECIDO | D4: MASCULINO | E4: 1
A5: GUABAL | B5: CALLE 13 CON CARRERA 43A | C5: 01 FALLECIDO | D5: FEMENINA | E5: 1
A6: MELENDEZ | B6: GRAN COLOMBIA 70 CON 2 | C6: 01 FALLECIDA 18 AñOS | D6: FEMENINA | E6: 1
A7: LIMONAR | B7: CRA 98B -48-127 | C7: 01 FALLECIDA | D7: FEMENINA | E7: 1
A8: LIMONAR | B8: CRA 72 CON 10-42 | C8: 02 FALLECIDA | D8: FEMENINA | E8: 2
A9: LIDO | B9: CL 5 CR 5b PAMPALINA | C9: 4 £EMININA5 Y 1 MASCULINO MAYORES DE EDAD | D9: M/£ | E9: 5
A10: LIDO | B10: cr 36a 5-145 b/ san fernanddo | C10: 01 MAYOR | D10: MASCULINO | E10: 1
A11: LIDO | B11: cl 5b2 38a-50 b/ san fernando | C11: 02 MAYOR | D11: MASCULINO | E11: 2
A12: LIDO | B12: cl 5a 43•5d b/ tequendama | C12: 02 MAYOR | D12: MAF | E12: 2
... A30: LIDO | B30: CL 3 CR 57 | C30: EUA VALENCIA 84 ANOS | D30: | FEMENINA | E30: 1
E31: =SUM(E1:E30) -> 47

Sheet Copia de Hoja2
A1: RECURSOS DE APOYO | B1: TRANSITO | C1: SGRD | D1: BROS | E1: DCC | F1: CRC
A3: BIADE | B3: 30
A4: Accesibilidad y transporte | C4: palmeto, utompista con 70 y notaria 20
A5: USAR | D5: POPAYAN TULUA PALMIRA BUGA YUMBO VILLA RICA | E5: X | F5: X
A6: Energia GAS
A7: Ingenieros estructurales | B7: Poliica Metropolitana Calle 41 norte 4 N 170 norte Carrera 56 calle 4 y calle 3

Sheet CAPACIADES 
B1: USAR MEIDANO | C1: CANINOS | D1: USAR LIBIA | E1: PERSONAL | F1: VEHICULOS | G1: CAMION | H1: Retro | I1: Minicargadores | J1: Volquetas | K1: Evaluacion estructuras | L1: Internet satelital
A2: BROS CALI | B2: 1 | E2: 260 | F2: 20
A3: BORS YUMBO | D3: 1 | E3: 15 | F3: 2
A4: POPAYAN | D4: 1 | E4: 15 | F4: 3
A5: VILLARICA | D5: 1 | E5: 15 | F5: 3
A6: JAMUNDI | D6: 1 | E6: 15 | F6: 2
A7: PALMIRA | D7: 1 | E7: 15 | F7: 2
A8: BOGOTA | D8: 1 | E8: 60
A9: CRC | E9: 102 | F9: 3
A10: SGRED | E10: 50 | F10: 4
A11: POLICIA | E11: 180
A12: INFRA | F12: 2
A13: DCC CALI | E13: 200 | F13: 4
A14: DCC-BOYACA | D14: 1 | E14: 15
A15: DCC-SANTANDER | D15: 1 | E15: 15
A16: DCC- NARIÑO | E16: 19
A17: MOVILDAD | E17: 250
A18: UAESP
A19: INFRAESTRUCTURA | E19: 20
A20: BIADE | B20: 1 | C20: 1 | E20: 55
A21: PASTO | B21: 1 | E21: 22
A22: PONALSAR | B22: 1 | C22: 2 | E22: 14
A23: ARMADA | B23: 1 | E23: 30
A24: METROCALI | E24: 20 | L24: 3
A25: SUESCA | E25: 5
E26: =SUM(E2:E25) -> 1392
A29: Diana Romero | B29: SUESCA | C29: 3192338267 | D29: 5 PERSONAS
